<?xml version="1.0" ?>
<!--
  Copyright (C) 2019  Rhys Mainwaring

  This program is free software: you can redistribute it and/or modify
  it under the terms of the GNU General Public License as published by
  the Free Software Foundation, either version 3 of the License, or
  (at your option) any later version.

  This program is distributed in the hope that it will be useful,
  but WITHOUT ANY WARRANTY; without even the implied warranty of
  MERCHANTABILITY or FITNESS FOR A PARTICULAR PURPOSE.  See the
  GNU General Public License for more details.

  You should have received a copy of the GNU General Public License
  along with this program.  If not, see <https://www.gnu.org/licenses/>.
-->
<sdf version="1.6">
  <world name="teleop_twist">
    
    <!-- Plugins -->
    <plugin name="joy" filename="libJoySDLPlugin.so">
      <joy_id>0</joy_id>
      <output_topic>/joy</output_topic>
      <rate>50</rate>
      <dead_zone>0.1</dead_zone>
    </plugin>

    <plugin name="teleop_twist_joy" filename="libTeleopTwistJoyPlugin.so">
      <input_topic>/joy</input_topic>
      <output_topic>/cmd_vel</output_topic>
      <enable_button>10</enable_button>
      <axis_linear>3</axis_linear>
      <scale_linear>1.0</scale_linear>
      <axis_angular>0</axis_angular>
      <scale_angular>1.0</scale_angular>
    </plugin>

    <!-- Lights -->
    <include>
      <uri>model://sun</uri>
    </include>

    <!-- World models  -->
    <include>
      <uri>model://ground_plane</uri>
    </include>

    <!-- Test model  -->
    <model name="thruster_test">
      <pose>0 0 0.5 0 0 0</pose>
      <static>false</static>

      <plugin name="link_joint_controller" filename="libLinkJointControllerPlugin.so">
        <input_topic>/cmd_vel</input_topic>
        <link_name>thruster_link</link_name>
        <link_scale>2</link_scale>
        <link_type>velocity</link_type>
        <link_pid>1000 0 10</link_pid>
        <joint_name>thruster_joint</joint_name>
        <joint_scale>0.8</joint_scale>
        <joint_type>position</joint_type>
        <joint_pid>1000 0 10</joint_pid>
      </plugin>

      <link name="base_link">
        <visual name="base_visual">
          <geometry>
            <box>
              <size>1 1 1</size>
            </box>
          </geometry>
          <material>
            <script>
              <name>Gazebo/Gray</name>
            </script>
          </material>
        </visual>
        <collision name="base_collision">
          <geometry>
            <box>
              <size>1 1 1</size>
            </box>
          </geometry>
        </collision>
        <inertial>
          <pose>0 0 0 0 0 0</pose>
          <mass>10</mass>
          <inertia>
            <ixx>1.6</ixx>
            <ixy>0</ixy>
            <iyy>1.6</iyy>
            <iyz>0</iyz>
            <izz>1.6</izz>
          </inertia>
        </inertial>

      </link>

      <!-- Thruster -->
      <link name="thruster_link">
        <pose>-1.5 0 0 0 0 0</pose>
        <visual name="thruster_visual">
          <geometry>
            <box>
              <size>1 1 1</size>
            </box>
          </geometry>
          <material>
            <script>
              <name>Gazebo/Black</name>
            </script>
          </material>
        </visual>
        <collision name="thruster_collision">
          <geometry>
            <box>
              <size>1 1 1</size>
            </box>
          </geometry>
        </collision>
        <inertial>
          <pose>0 0 0 0 0 0</pose>
          <mass>1</mass>
          <inertia>
            <ixx>0.16</ixx>
            <ixy>0</ixy>
            <iyy>0.16</iyy>
            <iyz>0</iyz>
            <izz>0.16</izz>
          </inertia>
        </inertial>
      </link>

      <joint type="revolute" name="thruster_joint">
        <pose>0.75 0 0 0 0 0</pose>
        <child>thruster_link</child>
        <parent>base_link</parent>
        <axis>
          <xyz>0 0 1</xyz>
          <limit>
            <lower>-0.8</lower>
            <upper>0.8</upper>
          </limit>
        </axis>
      </joint>
    </model>

  </world>
</sdf>
